<?xml version="1.0" encoding="UTF-8"?>
<testng-results skipped="0" failed="2" ignored="0" total="4" passed="2">
  <reporter-output>
  </reporter-output>
  <suite name="Default suite" duration-ms="8682" started-at="2021-02-07T07:07:17Z" finished-at="2021-02-07T07:07:25Z">
    <groups>
    </groups>
    <test name="Default test" duration-ms="8682" started-at="2021-02-07T07:07:17Z" finished-at="2021-02-07T07:07:25Z">
      <class name="Assignment.Assignment.Assignment1">
        <test-method status="PASS" signature="setup()[pri:0, instance:Assignment.Assignment.Assignment1@14acaea5]" name="setup" is-config="true" duration-ms="8642" started-at="2021-02-07T07:07:17Z" finished-at="2021-02-07T07:07:25Z">
          <reporter-output>
          </reporter-output>
        </test-method> <!-- setup -->
        <test-method status="FAIL" signature="Addition()[pri:0, instance:Assignment.Assignment.Assignment1@14acaea5]" name="Addition" duration-ms="6" started-at="2021-02-07T07:07:25Z" finished-at="2021-02-07T07:07:25Z">
          <exception class="java.lang.AssertionError">
            <message>
              <![CDATA[expected [111120] but found [111111]]]>
            </message>
            <full-stacktrace>
              <![CDATA[java.lang.AssertionError: expected [111120] but found [111111]
at org.testng.Assert.fail(Assert.java:96)
at org.testng.Assert.failNotEquals(Assert.java:776)
at org.testng.Assert.assertEqualsImpl(Assert.java:137)
at org.testng.Assert.assertEquals(Assert.java:118)
at org.testng.Assert.assertEquals(Assert.java:652)
at org.testng.Assert.assertEquals(Assert.java:662)
at Assignment.Assignment.Assignment1.Addition(Assignment1.java:59)
at sun.reflect.NativeMethodAccessorImpl.invoke0(Native Method)
at sun.reflect.NativeMethodAccessorImpl.invoke(Unknown Source)
at sun.reflect.DelegatingMethodAccessorImpl.invoke(Unknown Source)
at java.lang.reflect.Method.invoke(Unknown Source)
at org.testng.internal.MethodInvocationHelper.invokeMethod(MethodInvocationHelper.java:124)
at org.testng.internal.Invoker.invokeMethod(Invoker.java:583)
at org.testng.internal.Invoker.invokeTestMethod(Invoker.java:719)
at org.testng.internal.Invoker.invokeTestMethods(Invoker.java:989)
at org.testng.internal.TestMethodWorker.invokeTestMethods(TestMethodWorker.java:125)
at org.testng.internal.TestMethodWorker.run(TestMethodWorker.java:109)
at org.testng.TestRunner.privateRun(TestRunner.java:648)
at org.testng.TestRunner.run(TestRunner.java:505)
at org.testng.SuiteRunner.runTest(SuiteRunner.java:455)
at org.testng.SuiteRunner.runSequentially(SuiteRunner.java:450)
at org.testng.SuiteRunner.privateRun(SuiteRunner.java:415)
at org.testng.SuiteRunner.run(SuiteRunner.java:364)
at org.testng.SuiteRunnerWorker.runSuite(SuiteRunnerWorker.java:52)
at org.testng.SuiteRunnerWorker.run(SuiteRunnerWorker.java:84)
at org.testng.TestNG.runSuitesSequentially(TestNG.java:1208)
at org.testng.TestNG.runSuitesLocally(TestNG.java:1137)
at org.testng.TestNG.runSuites(TestNG.java:1049)
at org.testng.TestNG.run(TestNG.java:1017)
at org.testng.remote.AbstractRemoteTestNG.run(AbstractRemoteTestNG.java:132)
at org.testng.remote.RemoteTestNG.initAndRun(RemoteTestNG.java:236)
at org.testng.remote.RemoteTestNG.main(RemoteTestNG.java:81)
]]>
            </full-stacktrace>
          </exception> <!-- java.lang.AssertionError -->
          <reporter-output>
          </reporter-output>
        </test-method> <!-- Addition -->
        <test-method status="PASS" signature="Multiplication()[pri:0, instance:Assignment.Assignment.Assignment1@14acaea5]" name="Multiplication" duration-ms="2" started-at="2021-02-07T07:07:25Z" finished-at="2021-02-07T07:07:25Z">
          <reporter-output>
          </reporter-output>
        </test-method> <!-- Multiplication -->
        <test-method status="FAIL" signature="Substraction()[pri:0, instance:Assignment.Assignment.Assignment1@14acaea5]" name="Substraction" duration-ms="1" started-at="2021-02-07T07:07:25Z" finished-at="2021-02-07T07:07:25Z">
          <exception class="java.lang.AssertionError">
            <message>
              <![CDATA[expected [-22860000] but found [23329646]]]>
            </message>
            <full-stacktrace>
              <![CDATA[java.lang.AssertionError: expected [-22860000] but found [23329646]
at org.testng.Assert.fail(Assert.java:96)
at org.testng.Assert.failNotEquals(Assert.java:776)
at org.testng.Assert.assertEqualsImpl(Assert.java:137)
at org.testng.Assert.assertEquals(Assert.java:118)
at org.testng.Assert.assertEquals(Assert.java:652)
at org.testng.Assert.assertEquals(Assert.java:662)
at Assignment.Assignment.Assignment1.Substraction(Assignment1.java:71)
at sun.reflect.NativeMethodAccessorImpl.invoke0(Native Method)
at sun.reflect.NativeMethodAccessorImpl.invoke(Unknown Source)
at sun.reflect.DelegatingMethodAccessorImpl.invoke(Unknown Source)
at java.lang.reflect.Method.invoke(Unknown Source)
at org.testng.internal.MethodInvocationHelper.invokeMethod(MethodInvocationHelper.java:124)
at org.testng.internal.Invoker.invokeMethod(Invoker.java:583)
at org.testng.internal.Invoker.invokeTestMethod(Invoker.java:719)
at org.testng.internal.Invoker.invokeTestMethods(Invoker.java:989)
at org.testng.internal.TestMethodWorker.invokeTestMethods(TestMethodWorker.java:125)
at org.testng.internal.TestMethodWorker.run(TestMethodWorker.java:109)
at org.testng.TestRunner.privateRun(TestRunner.java:648)
at org.testng.TestRunner.run(TestRunner.java:505)
at org.testng.SuiteRunner.runTest(SuiteRunner.java:455)
at org.testng.SuiteRunner.runSequentially(SuiteRunner.java:450)
at org.testng.SuiteRunner.privateRun(SuiteRunner.java:415)
at org.testng.SuiteRunner.run(SuiteRunner.java:364)
at org.testng.SuiteRunnerWorker.runSuite(SuiteRunnerWorker.java:52)
at org.testng.SuiteRunnerWorker.run(SuiteRunnerWorker.java:84)
at org.testng.TestNG.runSuitesSequentially(TestNG.java:1208)
at org.testng.TestNG.runSuitesLocally(TestNG.java:1137)
at org.testng.TestNG.runSuites(TestNG.java:1049)
at org.testng.TestNG.run(TestNG.java:1017)
at org.testng.remote.AbstractRemoteTestNG.run(AbstractRemoteTestNG.java:132)
at org.testng.remote.RemoteTestNG.initAndRun(RemoteTestNG.java:236)
at org.testng.remote.RemoteTestNG.main(RemoteTestNG.java:81)
]]>
            </full-stacktrace>
          </exception> <!-- java.lang.AssertionError -->
          <reporter-output>
          </reporter-output>
        </test-method> <!-- Substraction -->
        <test-method status="PASS" signature="division()[pri:0, instance:Assignment.Assignment.Assignment1@14acaea5]" name="division" duration-ms="1" started-at="2021-02-07T07:07:25Z" finished-at="2021-02-07T07:07:25Z">
          <reporter-output>
          </reporter-output>
        </test-method> <!-- division -->
      </class> <!-- Assignment.Assignment.Assignment1 -->
    </test> <!-- Default test -->
  </suite> <!-- Default suite -->
</testng-results>
